Workbook

Sheet Kepala Sekolah
M1: Lampiran : I.a
A2: DATA KEPALA SEKOLAH
A3: UNIT KERJA : SMP NEGERI 2 KARANGTENGAH
A4: PER : 1 Agustus 2025
A7: No | B7: Nama dan Gelar | C7: Tempat Lahir | D7: Tanggal, Bulan, dan Tahun Lahir | E7: NIP (Nomor Induk Pegawai) | F7: NIK (Nomor Induk Kependudukan) | G7: Pangkat (Gol./Ruang) | I7: Pendidikan | K7: Memiliki Sertifikat Diklat Kepala Sekolah | M7: Alamat Tempat Tinggal
G8: Gol./ Ruang | H8: T.M.T | I8: Jenjang | J8: Jurusan / Bidang Studi | K8: Nomor | L8: Tanggal
A10: 1. | B10: PRIYANTONO, S.Pd., M.Pd. | C10: Demak | D10: 23950 | E10: 196902251994031005 | F10: 3374072502690001 | G10: Pembina Utama Muda, IV/c | H10: 43556 | I10: S.2 | J10: Magister Pendidikan Bahasa Indonesia | K10: 15023L0010321131013704 | L10: 42307 | M10: Jl. Kepala Gading III/377, Plamongan, Pedurungan, Kota Semarang
K12: Demak, Agustus 2025
K13: Kepala SMP Negeri 2 Karangtengah
K14: Kabupaten Demak
K17: PRIYANTONO, S.Pd., M.Pd.
K18: NIP. 196902251994031005

Sheet PNS, CPNS, PPPK~Guru
O1: Lampiran : I.b
A2: DATA PNS GURU, CPNS GURU, DAN PPPK GURU
A3: ='[1]Kepala Sekolah'!A3 -> UNIT KERJA : SMP NEGERI 2 KARANGTENGAH
A4: ='Kepala Sekolah'!A4 -> PER : 1 Agustus 2025
A6: No | B6: Mata Pelajaran Yang Diampu | C6: Tempat Lahir | D6: Tanggal, Bulan, dan Tahun Lahir | E6: Jenis Kelamin (L/P) | F6: Jenis Kepegawaian | G6: NIP (Nomor Induk Pegawai) | H6: NIK (Nomor Induk Kependudukan) | I6: Pangkat (Gol./Ruang) | K6: Pendidikan | M6: Terima Sertifikasi | O6: Alamat Tempat Tinggal
B7: Nama dan Gelar | F7: (PNS/ CPNS/ PPPK) | I7: Gol./Ruang | J7: T.M.T | K7: Jenjang Pendidikan | L7: Jurusan/Bidang Studi | M7: Sdh | N7: Blm
A8: Pendidikan Agama Islam
A9: 1. | B9: Titik Ardiati, S.Ag. | C9: Demak | D9: 28276 | E9: P | F9: PNS | G9: 197705312014062001 | H9: 3321037105770003 | I9: Penata Muda Tingkat I, III/b | J9: 43922 | K9: S1 | L9: Sarjana Agama | M9: v | O9: Bakalrejo, Guntur, Demak
A10: 2.
A11: Pendidikan Agama Kristen
B12: -
A13: Pendidikan Agama Katholik
B14: -
A15: Pendidikan Agama Hindu
B16: -
A17: Pendidikan Agama Budha
B18: -
A19: Bimbingan Konseling
A20: 1. | B20: Sri Rahayu, Sulistiyanti, S.Pd. | C20: Semarang | D20: 26337 | E20: P | F20: PPPK | G20: 197202082021212004 | H20: 3321104802720001 | I20: IX | J20: 44256 | K20: S1 | L20: BK | M20: v | O20: Katonsari, Demak, Demak
A21: 2.
A23: PPKn
A24: 1. | B24: Supriyono, S.Pd. | C24: Demak | D24: 25071 | E24: L | F24: PNS | G24: 196808212006041008 | H24: 3321112108680004 | I24: Penata Tingkat I, III/d | J24: 44470 | K24: S1 | L24: PPKn | M24: v | O24: Bintoro, Demak, Demak
A25: 2. | B25: Siti Koriyah, S.Pd. | C25: Demak | D25: 27806 | E25: P | F25: PPPK | G25: 197602162022212007 | H25: 3321065602760001 | I25: IX | J25: 44682 | K25: S1 | L25: PPKn | M25: v | O25: Wonosalam, Demak, Demak
A27: Bahasa Indonesia
A28: 1. | B28: ST. Astutik, S.Pd. | C28: Blora | D28: 28154 | E28: P | F28: PNS | G28: 197701292008012003 | H28: 3321036901770003 | I28: Pembina, IV/a | J28: 45017 | K28: S1 | L28: Pendidikan Bahasa Indonesia | M28: v | O28: Guntur, Guntur, Demak
A29: 2. | B29: Dewi Nur Khalimah, S.Pd., M.Pd. | C29: Demak | D29: 32089 | E29: P | F29: PNS | G29: 198711082010012013 | H29: 3321054811870001 | I29: Penata Tingkat I, III/d | J29: 44470 | K29: S2 | L29: Magister Pendidikan Bahasa Indonesia | M29: v | O29: Kadilangu, Bintoro, Demak
A30: 3. | B30: Lulu' Aulia, S.Pd. | C30: Demak | D30: 31874 | E30: P | F30: PPPK | G30: 198704072022212005 | H30: 3321054704870002 | I30: IX | J30: 44682 | K30: S1 | L30: Pendidikan Bahasa Indonesia | M30: v | O30: Karangsari, Karangtengah, Demak
A31: 4.
A33: Matematika
A34: 1. | B34: Paulius Muljono, S.Pd. | C34: Jakarta | D34: 27/09/1966 | E34: L | F34: PNS | G34: 196609271989031007 | H34: 3321042709660001 | I34: Pembina Utama Muda, IV/c | J34: 45444 | K34: S1 | L34: PPKn | M34: v | O34: Sembungharjo, Genuk, Semarang
A35: 2.
A36: 3.
A37: 4.
A39: Ilmu Pengetahuan Alam (IPA)
A40: 1. | B40: Malihatun Ni'mah, S.Si. | C40: Semarang | D40: 29447 | E40: P | F40: PNS | G40: 198008142009032003 | H40: 3322055408800006 | I40: Penata Tingkat I, III/d | J40: 44470 | K40: S1 | L40: Biologi | M40: v | O40: Jogoloyo, Wonosalam, Demak
A41: 2. | B41: Septia Nurkhalisa, S.Pd. | C41: Demak | D41: 35679 | E41: P | F41: PNS | G41: 199709062020122024 | H41: 3321114609970002 | I41: Penata Muda, III/a | J41: 44166 | K41: S1 | L41: Ilmu Pengetahuan Alam | M41: v | O41: Katonsari, Demak, Demak
A42: 3.
A44: Ilmu Pengetahuan Sosial (IPS)
A45: 1. | B45: Rita Krisnawati, S.Pd. | C45: Kudus | D45: 28068 | E45: P | F45: PNS | G45: 197611041999032003 | H45: 3321054411760001 | I45: Pembina Tingkat I, IV/b | J45: 45383 | K45: S1 | L45: Pendidikan Ekonomi | M45: v | O45: Mboyo, Karangtengah, Demak
A46: 2. | B46: Sri Haryati, S.Pd. | C46: Demak | D46: 25550 | E46: P | F46: PNS | G46: 196912132014062001 | H46: 3321055312690001 | I46: Penata Muda Tingkat I, III/b | J46: 45017 | K46: S1 | L46: Pendidikan Geografi | O46: Sayung, Demak
...

Sheet PNS~Pelaksana
K1: Lampiran : I.c
A2: DATA PEGAWAI NEGERI SIPIL (PNS) PELAKSANA
A3: ='[1]Kepala Sekolah'!A3 -> UNIT KERJA : SMP NEGERI 2 KARANGTENGAH
A4: ='Kepala Sekolah'!A4 -> PER : 1 Agustus 2025
A7: No | B7: Nama dan Gelar | C7: Tempat Lahir | D7: Tanggal, Bulan, dan Tahun Lahir | E7: NIP (Nomor Induk Pegawai) | F7: NIK (Nomor Induk Kependudukan) | G7: Pangkat (Gol./Ruang) | I7: Pendidikan | K7: Jenis/Tugas Pekerjaan | L7: Alamat Tempat Tinggal
G8: Gol./ Ruang | H8: T.M.T. | I8: Jenjang | J8: Jurusan/ Bidang Studi
A10: 1
A11: 2
J13: ='Kepala Sekolah'!K12 -> Demak, Agustus 2025
J14: ='[1]Kepala Sekolah'!K13 -> Kepala SMP Negeri 2 Karangtengah
J15: ='[1]Kepala Sekolah'!K14 -> Kabupaten Demak
J18: ='[1]Kepala Sekolah'!K17 -> PRIYANTONO, S.Pd., M.Pd.
J19: ='[1]Kepala Sekolah'!K18 -> NIP. 196902251994031005

Sheet GTT
L1: Lampiran : I.d
A2: DATA GURU TIDAK TETAP ( GTT )
A3: ='[1]Kepala Sekolah'!A3 -> UNIT KERJA : SMP NEGERI 2 KARANGTENGAH
A4: ='Kepala Sekolah'!A4 -> PER : 1 Agustus 2025
A6: No | B6: Mata Pelajaran Yang Diampu | C6: Tempat Lahir | D6: Tanggal, Bulan, Tahun Lahir | E6: Jenis Kelamin (L/P) | F6: NIK (Nomor Induk Kependidikan) | G6: SK Pengangkatan Sebagai GTT | L6: Mengajar Mata Pelajaran | M6: Status
B7: Nama dan Gelar | G7: Nomor SK | H7: Tanggal SK | I7: T.M.T. | J7: Pendidikan | M7: K2 | N7: Non K2
J8: Jenjang | K8: Jurusan
A9: Pendidikan Agama Islam
B10: -
A12: Pendidikan Agama Kristen
B13: -
A15: Pendidikan Agama Katholik
B16: -
A18: Pendidikan Agama Hindu
A21: Pendidikan Agama Budha
B22: -
A24: Bimbingan Konseling
A27: PPKn
B28: -
A30: Bahasa Indonesia
A34: Matematika
A37: Ilmu Pengetahuan Alam (IPA)
A40: Ilmu Pengetahuan Sosial (IPS)
B41: -
A43: Bahasa Inggris
A47: PJOK
A51: Seni Budaya
A54: Ketrampilan / Prakarya
B55: -
A57: Teknologi Informasi dan Komunikasi (TIK)
A60: Bahasa Jawa
B61: -
A63: Baca Tulis Al-Qur'an (BTQ)
K67: ='Kepala Sekolah'!K12 -> Demak, Agustus 2025
K68: ='[1]Kepala Sekolah'!K13 -> Kepala SMP Negeri 2 Karangtengah
K69: ='[1]Kepala Sekolah'!K14 -> Kabupaten Demak
K72: ='[1]Kepala Sekolah'!K17 -> PRIYANTONO, S.Pd., M.Pd.
K73: ='[1]Kepala Sekolah'!K18 -> NIP. 196902251994031005

Sheet PTT
L1: Lampiran : I.e
A2: DATA PEGAWAI TIDAK TETAP (PTT)
A3: ='[1]Kepala Sekolah'!A3 -> UNIT KERJA : SMP NEGERI 2 KARANGTENGAH
A4: ='Kepala Sekolah'!A4 -> PER : 1 Agustus 2025
A6: No | B6: Nama dan Gelar | C6: Tempat Lahir | D6: Tanggal, Bulan, Tahun Lahir | E6: Jenis Kelamin (L/P) | F6: NIK (Nomor Induk Kependudukan) | G6: SK Pengangkatan Sebagai PTT | L6: Tugas/Pekerjaan yang dikerjakan | M6: Status
G7: Nomor SK | H7: Tanggal SK | I7: T.M.T | J7: Pendidikan | M7: K2 | N7: Non K2
J8: Jenjang | K8: Jurusan
A9: 1 | B9: Trubus | C9: Demak | D9: 29020 | E9: L | F9: 3321051406790005 | G9: 421.2/022/2019 | H9: 43467 | I9: 39846 | J9: Paket C | K9: - | L9: Pengelola Keamanan dan Ketertiban Sekolah | N9: v
K11: ='Kepala Sekolah'!K12 -> Demak, Agustus 2025
K12: ='[1]Kepala Sekolah'!K13 -> Kepala SMP Negeri 2 Karangtengah
K13: ='[1]Kepala Sekolah'!K14 -> Kabupaten Demak
K16: ='[1]Kepala Sekolah'!K17 -> PRIYANTONO, S.Pd., M.Pd.
K17: ='[1]Kepala Sekolah'!K18 -> NIP. 196902251994031005

Sheet Kebutuhan Guru
I1: Lampiran : I.f
B2: JUMLAH KEBUTUHAN GURU PNS / CPNS / PPPK BERDASARKAN MATA PELAJARAN
B3: ( GURU TIDAK TETAP ( GTT) JANGAN DIIKUTKAN DIHITUNG )
B4: ='Kepala Sekolah'!A4 -> PER : 1 Agustus 2025
B6: NO. | C6: NAMA SEKOLAH | D6: JUMLAH MURID/ SISWA | E6: BIDANG STUDI / MATA PELAJARAN | F6: JML ROMBEL | G6: JUMLAH JAM PER MINGGU | H6: GURU YANG SEBENARNYA DIBUTUHKAN | I6: PNS GURU/CPNS GURU/PPPK, YANG ADA SAAT INI | J6: LEBIH ATAU KURANG GURU
H8: (Kolom 5 X 6) / 24
B9: 1 | C9: 2 | D9: 3 | E9: 4 | F9: 5 | G9: 6 | H9: 7 | I9: 8 | J9: 9
B11: 1. | C11: SMP Negeri 2 Karangtengah | D11: ='R10'!C6 -> 367 | E11: Pendidikan Agama Islam | F11: 13 | G11: 6 | H11: =(F11*G11)/24 -> 3.25 | I11: 1 | J11: =(I11-H11) -> -2.25
E12: Pendidikan Agama Kristen | F12: 0 | G12: 0 | H12: =(F12*G12)/24 -> 0 | I12: 0 | J12: =(I12-H12) -> 0
E13: Pendidikan Agama Katholik | F13: 0 | G13: 0 | H13: =(F13*G13)/24 -> 0 | I13: 0 | J13: =(I13-H13) -> 0
E14: Pendidikan Agama Hindu | F14: 0 | G14: 0 | H14: =(F14*G14)/24 -> 0 | I14: 0 | J14: =(I14-H14) -> 0
E15: Pendidikan Agama Budha | F15: 0 | G15: 0 | H15: =(F15*G15)/24 -> 0 | I15: 0 | J15: =(I15-H15) -> 0
E16: Bimbingan Konseling | F16: 13 | G16: 6 | H16: =D11/150 -> 2.4466667 | I16: 1 | J16: =(I16-H16) -> -1.4466667
E17: PPKn | F17: 13 | G17: 3 | H17: =(F17*G17)/24 -> 1.625 | I17: 2 | J17: =(I17-H17) -> 0.375
E18: Bahasa Indonesia | F18: 13 | G18: 6 | H18: =(F18*G18)/24 -> 3.25 | I18: 3 | J18: =(I18-H18) -> -0.25
E19: Matematika | F19: 13 | G19: 5 | H19: =(F19*G19)/24 -> 2.7083333 | I19: 1 | J19: =(I19-H19) -> -1.7083333
E20: IPA | F20: 13 | G20: 5 | H20: =(F20*G20)/24 -> 2.7083333 | I20: 2 | J20: =(I20-H20) -> -0.70833333
E21: IPS | F21: 13 | G21: 4 | H21: =(F21*G21)/24 -> 2.1666667 | I21: 3 | J21: =(I21-H21) -> 0.83333333
E22: Bahasa Inggris | F22: 13 | G22: 4 | H22: =(F22*G22)/24 -> 2.1666667 | I22: 2 | J22: =(I22-H22) -> -0.16666667
E23: PJOK | F23: 13 | G23: 3 | H23: =(F23*G23)/24 -> 1.625 | I23: 1 | J23: =(I23-H23) -> -0.625
E24: Seni Budaya/Prakarya | F24: 13 | G24: 3 | H24: =(F24*G24)/24 -> 1.625 | I24: 1 | J24: =(I24-H24) -> -0.625
E25: Teknologi Informasi dan Komunikasi (TIK) | F25: 13 | G25: 1 | H25: =D11/150 -> 2.4466667 | I25: 0 | J25: =(I25-H25) -> -2.4466667
E26: Bahasa Daerah | F26: 13 | G26: 2 | H26: =(F26*G26)/24 -> 1.0833333 | I26: 1 | J26: =(I26-H26) -> -0.083333333
E27: BTQ | F27: 13 | G27: 0 | H27: =(F27*G27)/24 -> 0 | I27: 0 | J27: =(I27-H27) -> 0
B30: Keterangan : | H30: ='Kepala Sekolah'!K12 -> Demak, Agustus 2025
B31: Kolom 3 : diisi berapa jumlah murid / siswa | H31: ='Kepala Sekolah'!K13 -> Kepala SMP Negeri 2 Karangtengah
B32: Kolom 7 : Jangan di Delete/dihapus karena sudah dirumus (Jml Rombel dikalikan Jml Jam Pel Per Minggu) dibagi 24 | H32: Kabupaten Demak
B33: Kolom 9 : Jangan di Delete/dihapus karena sudah dirumus (Jml Guru yang dibutuhkan dikurangi Jml Guru PNS saat ini)
B34: Pengisian Kebutuhan Guru BK dan Guru TIK dengan ketentuan 1 Guru mengampu 150-225 Siswa ( sudah dirumus jangan didelete)
B35: Apabila ada mata pelajaran yang belum tercantum dalam form dapat ditambahkan pada baris yang paling bawah | H35: PRIYANTONO, S.Pd., M.Pd.
H36: NIP. 196902251994031005

Sheet GURU
A1: DATA KESELURUHAN GURU
A2: =GTT!A3 -> UNIT KERJA : SMP NEGERI 2 KARANGTENGAH
A3: =GTT!A4 -> PER : 1 Agustus 2025
A5: Nama Sekolah | C5: : SMP Negeri 2 Karangtengah
A6: Kecamatan | C6: : Karangtengah
A7: Kabupaten | C7: : Demak
A8: Provinsi | C8: : Jawa Tengah
A10: No | B10: Nama Guru | C10: NIP | D10: PANGKAT/ GOLONGAN | E10: JABATAN | F10: STATUS KEPEGAWAIAN | G10: Mata Pelajaran | H10: Rombel | K10: JTM / Minggu | N10: JTM | O10: Tugas Tambahan | P10: Jumlah Tugas Tambahan | Q10: Jam Ekuivalen | R10: Total JTM | S10: Kebutuhan Guru | T10: Bezetting | U10: Kelebihan / Kekurangan
H11: Tkt 7 | I11: Tkt 8 | J11: Tkt 9 | K11: Tkt 7 | L11: Tkt 8 | M11: Tkt 9
A12: 1 | B12: TITIK ARDIATI, S.Ag. | C12: 197705312014062001 | D12: Penata, III/c | E12: GURU AHLI MUDA | F12: ASN | G12: Pendidikan Agama dan Budi Pekerti/Baca Tulis Al-Qur'an | H12: 4 | I12: 4 | J12: 2 | K12: 12 | L12: 12 | M12: 9 | N12: =SUM(H12:J13)*3 -> 69 | O12: Wali Kelas, Guru Piket | P12: 2 | Q12: 2 | R12: =SUM(N12:Q13) -> 77 | S12: =R12/24 -> 3.2083333 | T12: 2 | U12: =T12-S12 -> -1.2083333
B13: IKKE NAILUL AFIFAH, S.Pd., M.Pd. | C13: - | D13: - | E13: - | F13: NON DAPODIK | H13: 4 | I13: 4 | J13: 5 | K13: 4 | L13: 4 | M13: 14 | O13: Wali Kelas, Guru Piket, Petugas Perpus | P13: 2 | Q13: 2 | X13: Pangkat Golongan | Y13: Kelas Jabatan
A14: 2 | B14: SUPRIYONO, S.Pd. | C14: 196808212006041008 | D14: Pembina, IV/a | E14: GURU AHLI MADYA | F14: ASN | G14: Pendidikan Pancasila dan Kewarganegaraan | H14: 2 | I14: 1 | J14: 5 | K14: 9 | L14: 3 | M14: 15 | N14: =SUM(H14:J15)*3 -> 39 | O14: Guru Piket, Koor. P5 Kelas 7, Wakasek, Waka Kesiswaan | P14: 1 | Q14: 11 | R14: =SUM(N14:Q15) -> 69 | S14: =R14/24 -> 2.875 | T14: 2 | U14: =T14-S14 -> -0.875 | X14: Penata Muda, III/a | Y14: 8
B15: SITI KORIYAH, S.Pd. | C15: 197602162022212007 | D15: IX | E15: GURU AHLI PERTAMA | F15: ASN | H15: 2 | I15: 3 | K15: 9 | L15: 15 | O15: Wali Kelas, Guru Piket, Koor P5 Kelas 8, Tim STP2K, Ka Perpus | P15: 4 | Q15: 14 | X15: Penata Muda Tingkat I, III/b
A16: 3 | B16: ST. ASTUTIK, S.Pd. | C16: 197701292008012003 | D16: Pembina, IV/a | E16: GURU AHLI MADYA | F16: ASN | G16: Bahasa Indonesia | H16: 4 | K16: 24 | N16: =SUM(H16:J18)*3 -> 51 | O16: Wali Kelas, Guru Piket | P16: 2 | Q16: 2 | R16: =SUM(N16:Q18) -> 63 | S16: =R16/24 -> 2.625 | T16: 3 | U16: =T16-S16 -> 0.375 | X16: Penata, III/c | Y16: 9
B17: DEWI NUR KHALIMAH, S.Pd., M.Pd. | C17: 198711082010012013 | D17: Penata Tingkat I, III/d | E17: GURU AHLI MUDA | F17: ASN | I17: 4 | J17: 5 | L17: 18 | M17: 12 | O17: Wali Kelas, Guru Piket | P17: 2 | Q17: 2 | X17: Penata Tingkat I, III/d
B18: LULU' AULIA, S.Pd. | C18: 198704072022212005 | D18: IX | E18: GURU AHLI PERTAMA | F18: ASN | I18: 1 | J18: 3 | L18: 6 | M18: 18 | O18: Wali Kelas, Guru Piket, Petugas Perpus | P18: 2 | Q18: 2 | X18: Pembina, IV/a | Y18: 11
A19: 4 | B19: WUWUK RACHMAWATI, S.Pd., M.Pd. | C19: 198102182006042012 | D19: Pembina, IV/a | E19: GURU AHLI MADYA | F19: ASN | G19: Bahasa Inggris | I19: 4 | J19: 3 | L19: 16 | M19: 12 | N19: =SUM(H19:J20)*3 -> 39 | O19: Wali Kelas, Waka Sarpras, Guru Piket | P19: 2 | Q19: 2 | R19: =SUM(N19:Q20) -> 47 | S19: =R19/24 -> 1.9583333 | T19: 2 | U19: =T19-S19 -> 0.041666667 | X19: Pembina Tingkat I, IV/b
B20: RINA HAYATI, S.Pd. | C20: 197711262014062003 | D20: Penata Muda Tingkat I, III/b | E20: GURU AHLI PERTAMA | F20: ASN | H20: 4 | J20: 2 | K20: 16 | M20: 8 | O20: Wali kelas, Guru Piket | P20: 2 | Q20: 2 | X20: Pembina Utama Muda, IV/c
A21: 5 | B21: PAULUS MULJONO, S.Pd. | C21: 196609271989031007 | D21: Pembina Utama Muda, IV/c | E21: GURU AHLI MADYA | F21: ASN | G21: Matematika | H21: 2 | I21: 1 | J21: 4 | K21: 10 | L21: 5 | M21: 20 | N21: =SUM(H21:J22)*3 -> 39 | O21: Guru Piket, Bendahara Gaji | P21: 1 | Q21: 1 | R21: =SUM(N21:Q22) -> 45 | S21: =R21/24 -> 1.875 | T21: 2 | U21: =T21-S21 -> 0.125 | X21: Pembina Utama Madya, IV/d | Y21: 12
B22: M. NAILUL I'DAD FIRDAUS, S.Pd. | C22: - | D22: - | E22: - | F22: NON DAPODIK | H22: 2 | I22: 3 | J22: 1 | K22: 10 | L22: 15 | M22: 5 | O22: Wali kelas, Guru Piket | P22: 2 | Q22: 2 | X22: Pembina Utama, IV/e
A23: 6 | B23: MALIHATUN NI'MAH, S.Si. | C23: 198008142009032003 | D23: Penata Tingkat I, III/d | E23: GURU AHLI MUDA | F23: ASN | G23: Ilmu Pengetahuan Alam | H23: 2 | J23: 5 | K23: 10 | M23: 25 | N23: =SUM(H23:J24)*3 -> 39 | O23: Waka Kurikulum, Guru Piket, Koor. PKG | P23: 2 | Q23: 3 | R23: =SUM(N23:Q24) -> 49 | S23: =R23/24 -> 2.0416667 | T23: 2 | U23: =T23-S23 -> -0.041666667
B24: SEPTIA NURKHALISA, S.Pd. | C24: 199709062020122024 | D24: Penata Muda | E24: GURU AHLI PERTAMA | F24: ASN | H24: 2 | I24: 4 | K24: 10 | L24: 20 | O24: Wali Kelas, Guru piket | P24: 2 | Q24: 3
A25: 7 | B25: RITA KRISNAWATI, S.Pd. | C25: 197611041999032003 | D25: Pembina Tingkat I, IV/b | E25: GURU AHLI MADYA | F25: ASN | G25: Ilmu Pengetahuan Sosial | J25: 5 | M25: 20 | N25: =SUM(H25:J27)*3 -> 39 | O25: Guru Piket, Bendahara BOSP | P25: 1 | Q25: 2 | R25: =SUM(N25:Q27) -> 68 | S25: =R25/24 -> 2.8333333 | T25: 3 | U25: =T25-S25 -> 0.16666667
B26: SRI HARYATI, S.Pd. | C26: 196912132014062001 | D26: Penata Muda Tingkat I, III/b | E26: GURU AHLI PERTAMA | F26: ASN | H26: 2 | I26: 3 | K26: 8 | L26: 12 | O26: Wali Kelas, Guru Piket, Tim STP2K, Ka Laboratorium | P26: 3 | Q26: 4 | W26: =SUM(K26:L26:Q26) -> 27
B27: KHOIRUN NI'AM, S.E. | C27: 198402282022211014 | D27: IX | E27: GURU AHLI PERTAMA | F27: ASN | H27: 2 | I27: 1 | K27: 8 | L27: 4 | O27: Guru Piket, Koor. PKG, Tim STP2K, Koor. P5 Kelas 9, Dapodik, Bendahara Aset | P27: 4 | Q27: 15 | W27: =SUM(K27:L27,Q27) -> 27
A28: 8 | B28: DWI NUGROHO ANDY SUSETYO, S.S. | C28: 197510202009031003 | D28: Penata Tingkat I, III/d | E28: GURU AHLI MUDA | F28: ASN | G28: Bahasa Jawa | H28: 4 | I28: 4 | J28: 5 | K28: 8 | L28: 8 | M28: 10 | N28: =SUM(H28:J28)*3 -> 39 | O28: Wali Kelas, Koor. STP2K, Guru Piket | P28: 3 | Q28: 4 | R28: =SUM(N28:Q28) -> 46 | S28: =R28/24 -> 1.9166667 | T28: 1 | U28: =T28-S28 -> -0.91666667
A29: 9 | G29: Informatika | H29: -4 | I29: -4 | J29: -5 | K29: -12 | L29: -12 | M29: -15 | N29: =SUM(H29:J29)*3 -> -39 | R29: =SUM(N29:Q29) -> -39 | S29: =R29/24 -> -1.625 | T29: 0 | U29: =S29-T29 -> -1.625
A30: 10 | B30: ISTIKOMAH, S.Pd. | C30: 198704262022212004 | D30: IX | E30: GURU AHLI PERTAMA | F30: ASN | G30: Seni Budaya/Prakarya | H30: 3 | I30: 4 | J30: 5 | K30: 11 | L30: 12 | M30: 15 | N30: =SUM(H30:J31)*3 -> 39 | O30: Wali Kelas, Guru Piket | P30: 1 | Q30: 3 | R30: =SUM(N30:Q31) -> 45 | S30: =R30/24 -> 1.875 | T30: 2 | U30: =T30:T31-S30:S31 -> 0.125
B31: DIDIK PRABOWO, S.Pd. | C31: - | D31: - | E31: - | F31: NON DAPODIK | H31: 1 | K31: 1 | L31: 12 | M31: 15 | O31: Guru Piket | P31: 1 | Q31: 1
A32: 11 | B32: SRI WAHYUNI, S.Pd., M.Pd. | C32: 196806181994122003 | D32: Pembina Utama Muda, IV/c | E32: GURU AHLI MADYA | F32: ASN | G32: Penjasorkes | H32: 4 | I32: 4 | J32: 5 | K32: 12 | L32: 12 | M32: 15 | N32: =SUM(H32:J32)*3 -> 39 | O32: Pembina Ekstrakurikuler, Pembina UKS, Guru Piket, Waka Humas | P32: 2 | Q32: 3 | R32: =SUM(N32:Q32) -> 44 | S32: =R32/24 -> 1.8333333 | T32: 1 | U32: =T32-S32 -> -0.83333333
A33: 12 | B33: SRI RAHAYU SULISTIYANTI, S.Pd. | C33: 197202082021212004 | D33: IX | E33: GURU AHLI PERTAMA | F33: ASN | G33: Bimbingan Konseling | H33: 4 | I33: 4 | J33: 5 | K33: 4 | L33: 4 | M33: 5 | N33: =SUM(H33:J33)*3 -> 39 | O33: Guru Piket, Tim STP2K | P33: 2 | Q33: 3 | R33: =SUM(N33:Q33) -> 44 | S33: =R33/24 -> 1.8333333 | T33: 1 | U33: =T33-S33 -> -0.83333333
A35: Keterangan: | R35: Karangtengah, Agustus 2025
A36: 1. Tingkatan Kelas (Tkt) | R36: Kepala SMP Negeri 2 Karangtengah
A37: 2. Jam Tatap Muka Perminggu (JTM/Minggu)
A38: 3. Jumlah Tatap Muka (JTM)
A39: 4. Ketersediaan Pegawai (Bezetting)
R40: Priyantono, S.Pd., M.Pd.
R41: Pembina Utama Muda, IV/c
R42: NIP. 196902251994031005

Sheet TATA USAHA
A1: DATA KESELURUHAN PEGAWAI
A2: =PTT!A3 -> UNIT KERJA : SMP NEGERI 2 KARANGTENGAH
A3: =PTT!A4 -> PER : 1 Agustus 2025
B5: Nama Sekolah | D5: : SMP Negeri 2 Karangtengah
B6: Kecamatan | D6: : Karangtengah
B7: Kabupaten | D7: : Demak
B8: Provinsi | D8: : Jawa Tengah
B10: NO | C10: NAMA PEGAWAI | D10: NIP | E10: PANGKAT/GOL | F10: JABATAN | G10: STATUS KEPEGAWAIAN | H10: KEBUTUHAN PEGAWAI | I10: BEZETTING | J10: KELEBIHAN/KEKURANGAN
B11: 1 | C11: M. WILDAN REZKY TAWAKKAL, S.H. | D11: - | E11: - | F11: Koordinator Tata Usaha/Kepegawaian | G11: NON DAPODIK | I11: 1 | J11: =H11-I11 -> -1
B12: 2 | C12: DIVA AULIA SAJIDAH, S.Stat. | D12: - | E12: - | F12: Pengelola Administrasi Umum, Pengolah Data | G12: NON DAPODIK | I12: 1 | J12: =H12-I12 -> -1
B13: 3 | C13: TRUBUS | D13: - | E13: - | F13: Pengelola Keamanan dan Ketertiban Sekolah | G13: DAPODIK | I13: 1 | J13: =H13-I13 -> -1
B14: 4 | C14: SUROSO | D14: - | E14: - | F14: Pengelola Perpustakaan, Pranata Kearsipan, Inventaris Aset Sekolah | G14: NON DAPODIK | I14: 1 | J14: =H14-I14 -> -1
B15: 5 | C15: TUGIYO | D15: - | E15: - | F15: Pengelola Kebersihan Sekolah | G15: NON DAPODIK | I15: 1 | J15: =H15-I15 -> -1
B16: 6 | C16: SUNIMAN | D16: - | E16: - | F16: Penjaga Malam | G16: NON DAPODIK | I16: 1 | J16: =H16-I16 -> -1
B17: 7 | C17: JAMI'AN | D17: - | E17: - | F17: Penjaga Malam | G17: NON DAPODIK | I17: 1 | J17: =H17-I17 -> -1
H19: =GURU!R35 -> Karangtengah, Agustus 2025
H20: =GURU!R36 -> Kepala SMP Negeri 2 Karangtengah
H24: =GURU!R40 -> Priyantono, S.Pd., M.Pd.
H25: =GURU!R41 -> Pembina Utama Muda, IV/c
H26: =GURU!R42 -> NIP. 196902251994031005

Sheet STRUKTUR PETA JABATAN
A1: PETA JABATAN SMP NEGERI 2 KARANGTENGAH
A2: DINAS PENDIDIKAN DAN KEBUDAYAAN
A3: KABUPATEN DEMAK
I5: KEPALA SEKOLAH
A6: 19 ORANG TERDIRI DARI | I6: PRIYANTONO, S.Pd., M.Pd. | S6: BEBAN KERJA
A7: Es.I | B7: : | C7: Es.III | D7: : | E7: - | F7: JFT | G7: : 14 | I7: NIP. 196902251994031005 | S7: 1 | T7: PRIYANTONO, S.Pd., M.Pd. | U7: Kepala Sekolah
A8: Es.II | B8: : | C8: Es.IV | D8: : | E8: - | F8: JFU | G8: : 5 | S8: 2 | T8: PAULUS MULJONO, S.Pd. | U8: =GURU!O21 -> Guru Piket, Bendahara Gaji
S9: 3 | T9: SRI WAHYUNI, S.Pd., M.Pd. | U9: =GURU!O32 -> Pembina Ekstrakurikuler, Pembina UKS, Guru Piket, Waka Humas
A10: KEKUATAN PEGAWAI | S10: 4 | T10: RITA KRISNAWATI, S.Pd. | U10: =GURU!O25 -> Guru Piket, Bendahara BOSP
A11: IV/e : | B11: - | C11: III/d : | D11: 3 | E11: X : | G11: V : | H11: - | I11: I/d : | J11: - | S11: 5 | T11: ST. ASTUTIK, S.Pd. | U11: =GURU!O16 -> Wali Kelas, Guru Piket
A12: IV/d : | B12: - | C12: III/c : | D12: - | E12: IX : | F12: 5 | G12: II/d : | H12: - | I12: I/c : | J12: - | M12: WAKIL KEPALA | P12: WAKIL KEPALA | S12: 6 | T12: SUPRIYONO, S.Pd. | U12: =GURU!O14 -> Guru Piket, Koor. P5 Kelas 7, Wakasek, Waka Kesiswaan
A13: IV/c : | B13: 3 | C13: III/b : | D13: 3 | E13: VIII : | F13: - | G13: II/c : | H13: - | I13: I/b : | J13: - | M13: BIDANG AKADEMIK | P13: BIDANG KESISWAAN | S13: 7 | T13: WUWUK RACHMAWATI, S.Pd., M.Pd. | U13: =GURU!O19 -> Wali Kelas, Waka Sarpras, Guru Piket
A14: IV/b : | B14: 1 | C14: III/a : | D14: 1 | E14: VII : | F14: - | G14: II/b : | H14: - | I14: I/a : | J14: - | M14: MALIHATUN NI'MAH, S.Si. | P14: SUPRIYONO, S.Pd. | S14: 8 | T14: MALIHATUN NI'MAH, S.Si. | U14: =GURU!O23 -> Waka Kurikulum, Guru Piket, Koor. PKG
A15: IV/a : | B15: 3 | C15: XI : | D15: - | E15: VI : | F15: - | G15: II/a : | H15: - | M15: NIP. 198008142009032003 | P15: NIP. 196808212006041008 | S15: 9 | T15: DEWI NUR KHALIMAH, S.Pd., M.Pd. | U15: =GURU!O17 -> Wali Kelas, Guru Piket
S16: 10 | T16: DWI NUGROHO ANDY SUSETYO, S.S. | U16: =GURU!O28 -> Wali Kelas, Koor. STP2K, Guru Piket
S17: 11 | T17: TITIK ARDIATI, S.Ag. | U17: =GURU!O12 -> Wali Kelas, Guru Piket
S18: 12 | T18: SRI HARYATI, S.Pd. | U18: =GURU!O26 -> Wali Kelas, Guru Piket, Tim STP2K, Ka Laboratorium
S19: 13 | T19: RINA HAYATI, S.Pd. | U19: =GURU!O20 -> Wali kelas, Guru Piket
S20: 14 | T20: SEPTIA NURKHALISA, S.Pd. | U20: =GURU!O24 -> Wali Kelas, Guru piket
A21: KELOMPOK JABATAN FUNGSIONAL | G21: B | H21: K | L21: KELOMPOK JABATAN PELAKSANA | P21: B | Q21: K | S21: 15 | T21: SRI RAHAYU SULISTIYANTI, S.Pd. | U21: =GURU!O33 -> Guru Piket, Tim STP2K
A22: Guru Pendidikan Agama dan Budi Pekerti | G22: =GURU!T12 -> 2 | H22: =GURU!U12 -> -1.2083333 | L22: Kepegawaian, Analis Tata Usaha | P22: 1 | Q22: ='TATA USAHA'!J11 -> -1 | S22: 16 | T22: SITI KHOIRYAH, S.Pd. | U22: =GURU!O15 -> Wali Kelas, Guru Piket, Koor P5 Kelas 8, Tim STP2K, Ka Perpus
A23: Guru Pendidikan Pancasila dan Kewarganegaraan | G23: =GURU!T14 -> 2 | H23: =GURU!U14 -> -0.875 | L23: Pengelola Administrasi Umum, Pengolah Data | P23: 1 | Q23: ='TATA USAHA'!J12 -> -1 | S23: 17 | T23: KHOIRUN NI'AM, S.E. | U23: =GURU!O27 -> Guru Piket, Koor. PKG, Tim STP2K, Koor. P5 Kelas 9, Dapodik, Bendahara Aset
A24: Guru Bahasa Indonesia | G24: =GURU!T16 -> 3 | H24: =GURU!U16 -> 0.375 | L24: Pengelola Perpustakaan, Pranata Kearsipan, Inventaris Aset Sekolah | P24: 1 | Q24: ='TATA USAHA'!J14 -> -1 | S24: 18 | T24: LULU' AULIA, S.Pd. | U24: =GURU!O18 -> Wali Kelas, Guru Piket, Petugas Perpus
A25: Guru Bahasa Inggris | G25: =GURU!T19 -> 2 | H25: =GURU!U19 -> 0.041666667 | L25: Pengelola Keamanan dan Ketertiban Sekolah | P25: 1 | Q25: ='TATA USAHA'!J13 -> -1 | S25: 19 | T25: ISTIKOMAH, S.Pd. | U25: =GURU!O30 -> Wali Kelas, Guru Piket
A26: Guru Matematika | G26: =GURU!T21 -> 2 | H26: =GURU!U21 -> 0.125 | L26: Pengelola Kebersihan Sekolah | P26: 1 | Q26: ='TATA USAHA'!J15 -> -1 | S26: 20 | T26: DIDIK PRABOWO, S.Pd. | U26: =GURU!O31 -> Guru Piket
A27: Guru Ilmu Pengetahuan Alam | G27: =GURU!T23 -> 2 | H27: =GURU!U23 -> -0.041666667 | L27: Pengelola Barang Milik Negara/Aset Daerah | S27: 21 | T27: IKKE NAILUL AFIFAH, S.Pd., M.Pd.I. | U27: =GURU!O13 -> Wali Kelas, Guru Piket, Petugas Perpus
A28: Guru Ilmu Pengetahuan Sosial | G28: =GURU!T25 -> 3 | H28: =GURU!U25 -> 0.16666667 | L28: Bendahara | S28: 22 | T28: M. NAILUL I'DAD FIRDAUS, S.Pd. | U28: =GURU!O22 -> Wali kelas, Guru Piket
A29: Guru Bahasa Jawa | G29: =GURU!T28 -> 1 | H29: =GURU!U28 -> -0.91666667 | L29: Pramu Laboratorium | S29: 23 | T29: M. WILDAN REZKY TAWAKKAL, S.H. | U29: ='TATA USAHA'!F11 -> Koordinator Tata Usaha/Kepegawaian
A30: Guru Informatika | G30: =GURU!T29 -> 0 | H30: =GURU!U29 -> -1.625 | L30: Penjaga Malam | P30: 1 | Q30: ='TATA USAHA'!J16 -> -1 | S30: 24 | T30: DIVA AULIA SAJIDAH, S.Stat. | U30: ='TATA USAHA'!F12 -> Pengelola Administrasi Umum, Pengolah Data
A31: Guru Seni Budaya/Prakarya | G31: =GURU!T30 -> 2 | H31: =GURU!U30 -> 0.125 | L31: Penjaga Malam | P31: 1 | Q31: ='TATA USAHA'!J17 -> -1 | S31: 25 | T31: TRUBUS | U31: ='TATA USAHA'!F13 -> Pengelola Keamanan dan Ketertiban Sekolah
A32: Guru Penjasorkes | G32: =GURU!T32 -> 1 | H32: =GURU!U32 -> -0.83333333 | S32: 26 | T32: TUGIYO | U32: ='TATA USAHA'!F15 -> Pengelola Kebersihan Sekolah
A33: Guru BP/BK | G33: 1 | H33: =GURU!U33 -> -0.83333333 | S33: 27 | T33: SUROSO | U33: ='TATA USAHA'!F14 -> Pengelola Perpustakaan, Pranata Kearsipan, Inventaris Aset Sekolah
V35: =GURU!R35 -> Karangtengah, Agustus 2025
V36: =GURU!R36 -> Kepala SMP Negeri 2 Karangtengah
V40: =GURU!R40 -> Priyantono, S.Pd., M.Pd.
V41: =GURU!R41 -> Pembina Utama Muda, IV/c
V42: =GURU!R42 -> NIP. 196902251994031005

Sheet PETA JABATAN
B1: PETA JABATAN SMP NEGERI 2 KARANGTENGAH PADA DINAS PENDIDIKAN DAN KEBUDAYAAN KABUPATEN DEMAK
D3: KEPALA DINAS PENDIDIKAN DAN KEBUDAYAAN
D4: (KELAS 14)
B9: KEPALA SMP NEGERI 2 KARANGTENGAH
B10: (KELAS 11)
B13: Jabatan | D13: Kls | E13: B | F13: K | G13: +/-
B14: 1 | C14: Guru Ahli Madya | D14: 11 | E14: 2 | F14: 3 | G14: =E14-F14 -> -1
B15: 2 | C15: Guru Ahli Muda | D15: 9 | E15: 5 | F15: 6 | G15: =E15-F15 -> -1
B16: 3 | C16: Guru Ahli Pertama | D16: 8 | E16: 9 | F16: 5 | G16: =E16-F16 -> 4
B17: 4 | C17: Guru | D17: - | E17: 3 | F17: 4 | G17: =E17-F17 -> -1
B18: 5 | C18: Pengelola Kepegawaian | D18: - | E18: 1 | F18: 1 | G18: =E18-F18 -> 0
B19: 6 | C19: Pengadministrasi Keuangan | D19: - | E19: 0 | F19: 1 | G19: =E19-F19 -> -1
B20: 7 | C20: Pengadministrasi Umum | D20: - | E20: 1 | F20: 1 | G20: =E20-F20 -> 0
B21: 8 | C21: Petugas Keamanan | D21: - | E21: 1 | F21: 1 | G21: =E21-F21 -> 0
B22: 9 | C22: Pramu Kebersihan | D22: - | E22: 1 | F22: 1 | G22: =E22-F22 -> 0
H24: Demak,
H25: Kepala Dinas Pendidikan dan Kebudayaan
H30: Haris Wahyudi Ridwan, AP, M.Si
H31: Pembina Utama Muda
H32: NIP. 197606061995011001

Sheet PROYEKSI KEBUTUHAN PEGAWAI
A1: PROYEKSI KEBUTUHAN PEGAWAI 5 (LIMA) TAHUN KE DEPAN
A3: No | B3: Nama Unit Organisasi dan Nama Jabatan | C3: Bezetting Pegawai Saat Ini | D3: Kebutuhan Pegawai Berdasarkan ABK | E3: Proyeksi
E4: Jumlah yang akan Pensiun | J4: Pegawai yang Dibutuhkan
E5: 2025 | F5: 2026 | G5: 2027 | H5: 2028 | I5: 2029 | J5: 2025 | K5: 2026 | L5: 2027 | M5: 2028 | N5: 2029
A6: 1 | B6: 2 | C6: 3 | D6: 4 | E6: 5 | F6: 6 | G6: 7 | H6: 8 | I6: 9 | J6: 10 | K6: 11 | L6: 12 | M6: 13 | N6: 14
B7: Jumlah Seluruhnya | C7: =SUM(C10:C11,C16,C21,C26,C31,C36,C41,C46,C51,C56,C61) -> 21 | D7: =SUM(D10:D11,D16,D21,D26,D31,D36,D41,D46,D51,D56,D61) -> 26.291667 | E7: =SUM(E10:E77) -> 0 | F7: =SUM(F10:F77) -> 1 | G7: =SUM(G10:G77) -> 0 | H7: =SUM(H10:H77) -> 3 | I7: =SUM(I10:I77) -> 2 | J7: =SUM(J10:J11,J16,J21,J26,J31,J36,J41,J46,J51,J56,J61,J66,J71,J72,J73,J74,J75,J76,J77) -> 5.2916667 | K7: =SUM(K10:K11,K16,K21,K26,K31,K36,K41,K46,K51,K56,K61,K66,K71,K72,K73,K74,K75,K76,K77) -> 4.2916667 | L7: =SUM(L10:L11,L16,L21,L26,L31,L36,L41,L46,L51,L56,L61,L66,L71,L72,L73,L74,L75,L76,L77) -> 5.2916667 | M7: =SUM(M10:M11,M16,M21,M26,M31,M36,M41,M46,M51,M56,M61,M66,M71,M72,M73,M74,M75,M76,M77) -> 3.2916667 | N7: =SUM(N10:N11,N16,N21,N26,N31,N36,N41,N46,N51,N56,N61,N66,N71,N72,N73,N74,N75,N76,N77) -> 3.2916667
A8: Dinas Pendidikan dan Kebudayaan Kabupaten Demak
A9: SMP Negeri 2 Karangtengah
A10: 1 | B10: Kepala Sekolah | C10: 1 | D10: 1 | I10: 1 | J10: =D10-C10-E10 -> 0 | K10: =D10-C10-F10 -> 0 | L10: =D10-C10-G10 -> 0 | M10: =D10-C10-H10 -> 0 | N10: =D10-C10-I10 -> -1
A11: 2 | B11: Guru Pendidikan Agama dan Budi Pekerti | C11: =GURU!T12 -> 2 | D11: =GURU!S12 -> 3.2083333 | J11: =D11-C11-E11 -> 1.2083333 | K11: =D11-C11-F11 -> 1.2083333 | L11: =D11-C11-G11 -> 1.2083333 | M11: =D11-C11-H11 -> 1.2083333 | N11: =D11-C11-I11 -> 1.2083333
B12: a. Guru Utama - 13
B13: b. Guru Madya - 11
B14: c. Guru Muda - 9 | C14: 1
B15: d. Guru Pertama - 8
A16: 3 | B16: Guru Pendidikan Pancasila dan Kewarganegaraan | C16: =GURU!T14 -> 2 | D16: =GURU!S12 -> 3.2083333 | H16: 1 | J16: =D16-C16-E16 -> 1.2083333 | K16: =D16-C16-F16 -> 1.2083333 | L16: =D16-C16-G16 -> 1.2083333 | M16: =D16-C16-H16 -> 0.20833333 | N16: =D16-C16-I16 -> 1.2083333
B17: a. Guru Utama - 13
B18: b. Guru Madya - 11 | C18: 1
B19: c. Guru Muda - 9
B20: d. Guru Pertama - 8 | C20: 1
A21: 4 | B21: Guru Bahasa Indonesia | C21: =GURU!T16 -> 3 | D21: =GURU!S16 -> 2.625 | J21: =D21-C21-E21 -> -0.375 | K21: =D21-C21-F21 -> -0.375 | L21: =D21-C21-G21 -> -0.375 | M21: =D21-C21-H21 -> -0.375 | N21: =D21-C21-I21 -> -0.375
B22: a. Guru Utama - 13
B23: b. Guru Madya - 11 | C23: 1
B24: c. Guru Muda - 9 | C24: 1
B25: d. Guru Pertama - 8 | C25: 1
A26: 5 | B26: Guru Bahasa Inggris | C26: =GURU!T19 -> 2 | D26: =GURU!S19 -> 1.9583333 | J26: =D26-C26-E26 -> -0.041666667 | K26: =D26-C26-F26 -> -0.041666667 | L26: =D26-C26-G26 -> -0.041666667 | M26: =D26-C26-H26 -> -0.041666667 | N26: =D26-C26-I26 -> -0.041666667
B27: a. Guru Utama - 13
B28: b. Guru Madya - 11 | C28: 1
B29: c. Guru Muda - 9
B30: d. Guru Pertama - 8 | C30: 1
A31: 6 | B31: Guru Matematika | C31: =GURU!T21 -> 2 | D31: =GURU!S21 -> 1.875 | F31: 1 | J31: =D31-C31-E31 -> -0.125 | K31: =D31-C31-F31 -> -1.125 | L31: =D31-C31-G31 -> -0.125 | M31: =D31-C31-H31 -> -0.125 | N31: =D31-C31-I31 -> -0.125
B32: a. Guru Utama - 13
B33: b. Guru Madya - 11 | C33: 1
B34: c. Guru Muda - 9
B35: d. Guru Pertama - 8
A36: 7 | B36: Guru Ilmu Pengetahuan Alam | C36: =GURU!T23 -> 2 | D36: =GURU!S23 -> 2.0416667 | J36: =D36-C36-E36 -> 0.041666667 | K36: =D36-C36-F36 -> 0.041666667 | L36: =D36-C36-G36 -> 0.041666667 | M36: =D36-C36-H36 -> 0.041666667 | N36: =D36-C36-I36 -> 0.041666667
B37: a. Guru Utama - 13
B38: b. Guru Madya - 11
B39: c. Guru Muda - 9 | C39: 1
B40: d. Guru Pertama - 8 | C40: 1
A41: 8 | B41: Guru Ilmu Pengetahuan Sosial | C41: =GURU!T25 -> 3 | D41: =GURU!S25 -> 2.8333333 | I41: 1 | J41: =D41-C41-E41 -> -0.16666667 | K41: =D41-C41-F41 -> -0.16666667 | L41: =D41-C41-G41 -> -0.16666667 | M41: =D41-C41-H41 -> -0.16666667 | N41: =D41-C41-I41 -> -1.1666667
...

Sheet R7
A1: PEMERINTAH KABUPATEN DEMAK | U1: R.7
A2: DINAS PENDIDIKAN DAN KEBUDAYAAN
A3: SMP NEGERI 2 KARANGTENGAH
A4: DAFTAR URUT KEPANGKATAN (DUK) PEGAWAI NEGERI SIPIL DAN NON PNS
A5: PER 1 AGUSTUS 2025
A7: NO | B7: NAMA | C7: L/P | D7: NIP/ KARPEG | E7: PANGKAT | H7: JABATAN | J7: MASA KERJA KESELURUHAN | L7: LATIHAN JABATAN | P7: IJAZAH | Q7: JURUSAN | R7: TAHUN | S7: TGL LAHIR | T7: CTT MUTASI | U7: KET
E8: GOLONGAN | F8: JABATAN | G8: TMT | H8: NAMA | I8: TMT | J8: TAHUN | K8: BULAN | L8: NAMA | M8: TAHUN | N8: BULAN | O8: JUMLAH JAM
A9: 1 | B9: 2 | C9: 3 | D9: 4 | E9: 5 | G9: 6 | H9: 7 | I9: 8 | J9: 9 | K9: 10 | L9: 13 | M9: 14 | N9: 15 | O9: 16 | P9: 17 | Q9: 18 | R9: 19 | S9: 20 | T9: 21 | U9: 23
A10: 1 | B10: PRIYANTONO, S.Pd., M.Pd. | C10: L | D10: 196902251994031005 | E10: Pembina Utama Muda, IV/c | F10: Guru Ahli Madya | G10: 43553 | H10: GURU | I10: 34394 | J10: 31 | K10: 5 | L10: STTPL | M10: 1995 | N10: JULI | O10: 300 | P10: D3 | Q10: BAHASA JAWA | R10: 1992 | S10: 25259 | T10: SMPN 3 GUNTUR | U10: 43739
D11: G.174615 | H11: KS | I11: 43739 | J11: 5 | K11: 10 | L11: STTPL KS | M11: 2015 | N11: OKTOBER | P11: S2 | Q11: BAHASA INDONESIA | R11: 2013
A12: 2 | B12: PAULUS MULJONO, S.Pd. | C12: L | D12: 196609271989031007 | E12: Pembina Utama Muda, IV/c | F12: Guru Ahli Madya | G12: 45444 | H12: GURU | I12: 32568 | J12: 36 | K12: 5 | L12: STTPL | M12: 1990 | N12: JULI | O12: 301 | P12: S1 | Q12: PKn | R12: 2009 | S12: 24377
D13: E.851146
A14: 3 | B14: SRI WAHYUNI, S.Pd., M.Pd. | C14: P | D14: 196806181994122003 | E14: Pembina Utama Muda, IV/c | F14: Guru Ahli Madya | G14: 45627 | H14: GURU | I14: 34669 | J14: 31 | K14: 7 | L14: STTPL | M14: 1995 | N14: JULI | O14: 300 | P14: S1 | Q14: PENJASORKES | R14: 1993 | S14: 25007 | T14: SMPN 30 MAKASSAR | U14: 38534
D15: G.331964 | P15: S2 | Q15: MANAJEMEN PENDIDIKAN | R15: 2017
A16: 4 | B16: RITA KRISNAWATI, S.Pd. | C16: P | D16: 197611041999032003 | E16: Pembina Tingkat I, IV/b | F16: Guru Ahli Madya | G16: 45383 | H16: GURU | I16: 36220 | J16: 26 | K16: 4 | L16: STTPL | M16: 2000 | N16: JULI | O16: 182 | P16: S1 | Q16: EKONOMI | R16: 1998 | S16: 28068 | T16: SMPN 3 BONANG | U16: 45352
D17: J.013213
A18: 5 | B18: ST. ASTUTIK, S.Pd. | C18: P | D18: 197701292008012003 | E18: Pembina, IV/a | F18: Guru Ahli Madya | G18: 44927 | H18: GURU | I18: 39448 | J18: 17 | K18: 7 | L18: STTPL | M18: 2009 | N18: JUNI | O18: 216 | P18: S1 | Q18: BAHASA INDONESIA | R18: 2001 | S18: 28154
D19: N.569078
A20: 6 | B20: SUPRIYONO, S.Pd. | C20: L | D20: 196808212006041008 | E20: Pembina, IV/a | F20: Guru Ahli Madya | G20: 45870 | H20: GURU | I20: 39508 | J20: 17 | K20: 4 | L20: STTPL | M20: 2007 | N20: JUNI | O20: 135 | P20: S1 | Q20: PPKn | R20: 1997 | S20: 25071
D21: N.049946
A22: 7 | B22: WUWUK RACHMAWATI, S.Pd., M.Pd. | C22: P | D22: 198102182006042012 | E22: Pembina, IV/a | F22: Guru Ahli Madya | G22: 45870 | H22: GURU | I22: 39417 | J22: 17 | K22: 5 | L22: STTPL | M22: 2006 | N22: JULI | O22: 148 | P22: S1 | Q22: BAHASA INGGRIS | R22: 2005 | S22: 29635
D23: N.046691 | P23: S2 | Q23: MANAJEMEN PENDIDIKAN
A24: 8 | B24: DWI NUGROHO ANDY SUSETYO, S.S. | C24: L | D24: 197510202009031003 | E24: Penata Tingkat I, III/d | F24: Guru Ahli Muda | G24: 44565 | H24: GURU | I24: 40452 | J24: 24 | K24: 10 | L24: STTPL | M24: 2010 | N24: JULI | O24: 135 | P24: S1 | Q24: BAHASA JAWA | R24: 2000 | S24: 27687
D25: P.342175
A26: 9 | B26: MALIHATUN NI'MAH, S.Si. | C26: P | D26: 198008142009032003 | E26: Penata Tingkat I, III/d | F26: Guru Ahli Muda | G26: 44206 | H26: GURU | I26: 40452 | J26: 24 | K26: 10 | L26: STTPL | M26: 2010 | N26: JULI | O26: 135 | P26: S1 | Q26: BIOLOGI | R26: 2004 | S26: 29447
D27: P.342174
A28: 10 | B28: DEWI NUR KHALIMAH, S.Pd., M.Pd. | C28: P | D28: 198711082010122013 | E28: Penata Tingkat I, III/d | F28: Guru Ahli Muda | G28: 44206 | H28: GURU | I28: 40909 | J28: 13 | K28: 6 | L28: STTPL | M28: 2011 | N28: JULI | O28: 136 | P28: S1 | Q28: BAHASA INDONESIA | R28: 2011 | S28: 32000 | T28: SMP SATAP UNGARAN | U28: 44743
D29: Q.031767 | P29: S2 | Q29: BAHASA INDONESIA
A30: 11 | B30: TITIK ARDIATI, S.Ag. | C30: P | D30: 197705312014062001 | E30: Penata, III/c | F30: Guru Ahli Muda | G30: 45870 | H30: GURU | I30: 42522 | J30: 9 | K30: 2 | L30: STTPL | M30: 2015 | N30: OKTOBER | P30: S1 | Q30: TARBIYAH | R30: 1999 | S30: 28276
D31: B.01014744
A32: 12 | B32: SRI HARYATI, S.Pd. | C32: P | D32: 196912132014062001 | E32: Penata Muda Tingkat I, III/b | F32: Guru Ahli Pertama | G32: 44958 | H32: GURU | I32: 42522 | J32: 9 | K32: 2 | L32: STTPL | M32: 2015 | N32: OKTOBER | P32: S1 | Q32: GEOGRAFI | R32: 2003 | S32: 25550 | T32: SMPN 2 SAYUNG | U32: 43647
D33: B.01014899
A34: 13 | B34: RINA HAYATI, S.Pd. | C34: P | D34: 197711262014062003 | E34: Penata Muda Tingkat I, III/b | F34: Guru Ahli Pertama | G34: 45566 | H34: GURU | I34: 42522 | J34: 9 | K34: 2 | L34: STTPL | M34: 2015 | N34: OKTOBER | P34: S1 | Q34: BAHASA INGGRIS | R34: 2003 | S34: 28455
D35: B.01014742
A36: 14 | B36: SEPTIA NURKHALISA, S.Pd. | C36: P | D36: 199709062020122024 | E36: Penata Muda, III/a | F36: Guru Ahli Pertama | G36: 43842 | H36: GURU | I36: 43842 | J36: 5 | K36: 6 | L36: STTPL | M36: 2001 | P36: S1 | Q36: ILMU PENGETAHUAN ALAM | R36: 2019 | S36: 35590
D37: B.01061819
A38: 15 | B38: SRI RAHAYU SULISTIYANTI, S.Pd. | C38: P | D38: 197202082021212004 | E38: IX | F38: Guru Ahli Pertama | G38: 44197 | H38: GURU | I38: 44197 | J38: 4 | K38: 6 | P38: S1 | Q38: BP | R38: 2002 | S38: 26337
A40: 16 | B40: SITI KORIYAH, S.Pd. | C40: P | D40: 197602162022212007 | E40: IX | F40: Guru Ahli Pertama | G40: 44682 | H40: GURU | I40: 44682 | J40: 3 | K40: 3 | P40: S1 | Q40: PKn | R40: 2009 | S40: 27806
A42: 17 | B42: KHOIRUN NI'AM, S.E. | C42: L | D42: 198402282022211014 | E42: IX | F42: Guru Ahli Pertama | G42: 44682 | H42: GURU | I42: 44682 | J42: 3 | K42: 3 | P42: S1 | Q42: EKONOMI PEMBANGUNAN | R42: 2006 | S42: 30740
A44: 18 | B44: LULU AULIA, S.Pd. | C44: P | D44: 198704072022212005 | E44: IX | F44: Guru Ahli Pertama | G44: 44682 | H44: GURU | I44: 44682 | J44: 3 | K44: 3 | P44: S1 | Q44: BAHASA INDONESIA | R44: 2011 | S44: 31874
...

Sheet R8
A1: DAFTAR URUT KEPANGKATAN | S1: R8
A2: PER 1 AGUSTUS 2025
A3: UNIT ORGANISASI : DINAS PENDIDIKAN DAN KEBUDAYAAN KABUPATEN DEMAK
A4: TEMPAT : SMP NEGERI 2 KARANGTENGAH
A6: NO URUT | B6: NAMA | C6: L/P | D6: NIP/KARPEG | E6: PANGKAT | G6: JABATAN | I6: MASA KERJA KESELURUHAN | K6: LATIHAN JABATAN | O6: PENDIDIKAN | R6: TGL LAHIR | S6: CTT MUTASI | T6: KET
E7: GOLRU | F7: TMT | G7: NAMA | H7: TMT | I7: THN | J7: BLN | K7: NAMA | L7: TAHUN | M7: BULAN | N7: JML JAM | O7: NAMA | P7: LULUS THN | Q7: TINGKAT IJAZAH
A8: 1 | B8: 2 | C8: 3 | D8: 4 | E8: 5 | F8: 6 | G8: 7 | H8: 8 | I8: 9 | J8: 10 | K8: 11 | L8: 12 | M8: 13 | N8: 14 | O8: 15 | P8: 16 | Q8: 17 | R8: 18 | S8: 19 | T8: 20
A9: 1 | B9: M. WILDAN REZKY TAWAKKAL, S.H. | C9: L | D9: - | E9: - | F9: - | G9: PTT | H9: 45383 | I9: 1 | J9: 4 | K9: - | L9: - | M9: - | N9: - | O9: SARJANA ILMU HUKUM | P9: 2021 | Q9: S1 | R9: 34885
D10: - | E10: - | F10: - | K10: - | L10: - | M10: - | N10: -
A11: 2 | B11: DIVA AULIA SAJIDAH, S.Stat. | C11: P | D11: - | E11: - | F11: - | G11: PTT | H11: 01-03-2025 | I11: 0 | J11: 5 | K11: - | L11: - | M11: - | N11: - | O11: SARJANA STATISTIKA | P11: 2024 | Q11: S1 | R11: 37520
D12: - | E12: - | F12: - | K12: - | L12: - | M12: - | N12: -
A13: 5 | B13: TRUBUS | C13: L | D13: - | E13: - | F13: - | G13: PENGELOLA KEAMANAN & KETERTIBAN SEKOLAH | H13: 39846 | I13: 16 | J13: 1 | K13: - | L13: - | M13: - | N13: - | O13: PAKET C | P13: 2014 | Q13: PAKET C | R13: 29020
D14: - | E14: - | F14: - | K14: - | L14: - | M14: - | N14: -
A15: 4 | B15: SUROSO | C15: L | D15: - | E15: - | F15: - | G15: PTT | H15: 44013 | I15: 4 | J15: 10 | K15: - | L15: - | M15: - | N15: - | O15: SEKOLAH TEKNIK MENENGAH | P15: 1983 | Q15: STM | R15: 22991
D16: - | E16: - | F16: - | K16: - | L16: - | M16: - | N16: -
A17: 6 | B17: TUGIYO | C17: L | D17: - | E17: - | F17: - | G17: PTT | H17: 44744 | I17: 3 | J17: 1 | K17: - | L17: - | M17: - | N17: - | O17: PAKET C | P17: 1983 | Q17: PAKET C | R17: 22811
D18: - | E18: - | F18: - | K18: - | L18: - | M18: - | N18: -
A19: 7 | B19: SUNIMAN | C19: L | D19: - | E19: - | F19: - | G19: PENJAGA MALAM | H19: 34547 | I19: 31 | J19: 0 | K19: - | L19: - | M19: - | N19: - | O19: SR | P19: - | Q19: SD | R19: 17365
D20: - | E20: - | F20: - | K20: - | L20: - | M20: - | N20: -
A21: 8 | B21: JAMI`AN | C21: L | D21: - | E21: - | F21: - | G21: PENJAGA MALAM | H21: 42492 | I21: 9 | J21: 1 | K21: - | L21: - | M21: - | N21: - | O21: PAKET C | P21: 2008 | Q21: PAKET C | R21: 25730
D22: - | E22: - | F22: - | K22: - | L22: - | M22: - | N22: -
Q24: =GURU!R35 -> Karangtengah, Agustus 2025
Q25: =GURU!R36 -> Kepala SMP Negeri 2 Karangtengah
Q29: =GURU!R40 -> Priyantono, S.Pd., M.Pd.
Q30: =GURU!R41 -> Pembina Utama Muda, IV/c
Q31: =GURU!R42 -> NIP. 196902251994031005

Sheet R10
H1: REKAPITULASI DATA KETENAGAAN (SMP) | Q1: R.10
B2: Kelas | C2: Jmh Murid | D2: Jmh Kelas | H2: UNIT KERJA | J2: : SMPN 2 KARANGTENGAH
B3: VII | C3: 117 | D3: 4 | H3: ALAMAT | J3: : Jl. Raya Donorejo
B4: VIII | C4: 134 | D4: 4 | H4: KEC/KAB | J4: : Karangtengah / Demak
B5: IX | C5: 116 | D5: 5 | H5: NO TELP | J5: : 02916910950
B6: Jumlah | C6: =SUM(C3:C5) -> 367 | D6: =SUM(D3:D5) -> 13
A8: No | B8: Bidang Studi | C8: Jumlah | G8: GT Yang ada | K8: Saran Kepala Sekolah | O8: Jumlah | S8: Keterangan
C9: Kebutuhan Guru | G9: Berdasarkan Ijazah | K9: Perlu Ditambah | M9: Perlu Dikurangi | O9: GTT/SKB | Q9: GB
A10: 1 | B10: 2 | C10: 3 | G10: 4 | K10: 5 | M10: 6 | O10: 7 | Q10: 8 | S10: 9
A11: 1 | B11: Pendidikan Agama Islam/Baca Tulis Qur'an | C11: =GURU!S12 -> 3.2083333 | G11: 1
A12: 6 | B12: PPKn | C12: =GURU!S14 -> 2.875 | G12: 2 | K12: 1 | S12: 1 Pensiun 1 Agustus 2028
A13: 7 | B13: Penjas / Orkes | C13: =GURU!S32 -> 1.8333333 | G13: 1 | K13: 1 | S13: Pensiun 1 Juni 2028
A14: 12 | B14: Seni Budaya/Prakarya | C14: =GURU!S30 -> 1.875 | G14: 1 | K14: 1 | O14: 1
A15: 13 | B15: B. Indonesia | C15: =GURU!S16 -> 2.625 | G15: 3
A16: 14 | B16: B. Jawa | C16: =GURU!S28 -> 1.9166667 | G16: 1
A17: 15 | B17: B. Inggris | C17: =GURU!S19 -> 1.9583333 | G17: 2
A18: 17 | B18: Matematika | C18: =GURU!S21 -> 1.875 | G18: 1 | K18: 1 | O18: 1 | S18: Pensiun 1 Oktober 2026
A19: 18 | B19: IPA | C19: =GURU!S23 -> 2.0416667 | G19: 2
A20: 22 | B20: IPS | C20: =GURU!S25 -> 2.8333333 | G20: 3 | K20: 1 | S20: Pensiun 1 Desember 2029
A21: 28 | B21: TIK/Informatika | C21: =GURU!S29 -> -1.625 | S21: Pensiun 1 April 2025
A22: 30 | B22: BP/BK | C22: =GURU!S33 -> 1.8333333 | G22: 1 | K22: 1
A23: Jumlah | C23: =SUM(C11:F22) -> 23.25 | G23: =SUM(G11:J22) -> 18 | K23: =SUM(K11:L22) -> 6 | O23: =SUM(O11:P22) -> 2 | Q23: =SUM(Q11:Q22) -> 0
A25: Pegawai | B25: I | G25: II | K25: III | O25: IV
A26: Golongan | B26: a | C26: b | D26: c | E26: d | F26: d | G26: a | H26: b | I26: c | J26: d | K26: a | L26: b | M26: c | N26: d | O26: a | P26: b | Q26: c | R26: d | S26: e
A27: Koor TU
A28: Tata Usaha
A29: Pesuruh
A30: Penj. Malam
A32: TTT | B32: SD | C32: : | E32: 1 | F32: SMP | G32: : | I32: - | J32: SLTA/Diploma: | N32: 4 | O32: Sarjana | Q32: : | R32: 4
A33: Pustakawan | B33: Berdasarkan SK Menteri/Kanwil | N33: : | O33: Ada/Tidak Ada*)
A34: Laboran | B34: Berdasarkan SK Menteri/Kanwil | N34: : | O34: Ada/Tidak Ada*)
B36: Catatan | C36: : | D36: Isian Bidang Studi Bisa ditambah / dikurangi sesuai kebutuhan
C37: *) | D37: Coret yang tidak perlu
C38: JANGAN MERUBAH FORMAT | P38: =GURU!R35 -> Karangtengah, Agustus 2025
P39: =GURU!R36 -> Kepala SMP Negeri 2 Karangtengah
P43: =GURU!R40 -> Priyantono, S.Pd., M.Pd.
P44: =GURU!R41 -> Pembina Utama Muda, IV/c
P45: =GURU!R42 -> NIP. 196902251994031005
