Workbook
Name _Hlk173475416: Sheet1!$C$27

Sheet Sheet1
B2: PEMERINTAH KABUPATEN DEMAK
B3: SMP NEGERI 2 KARANGTENGAH
B4: Jalan Raya Donorejo Kec. Karangtengah Demak, Jawa Tengah 59561
B5: (0291) 6910950 Pos-el : smpn2.karangtengahdemak@yahoo.co.id
B7: SURAT PERINTAH TUGAS
B8: No : 800/106/2025
B10: Dasar : | C10: 1. Peraturan Menteri Keuangan Nomor 113/PMK.05/2012
C11: 2. Peraturan Pemerintah Nomor 12 Tahun 2019
C12: 3. Peraturan Daerah Kabupaten Demak Nomor 7 Tahun 2021
C13: 4. Peraturan Bupati Demak Nomor 53 Tahun 2021
C14: 5. Peraturan Bupati Demak Nomor 29 Tahun 2023
B16: MEMERINTAHKAN :
B18: Kepada : | C18: 1. Nama | D18: : | E18: Malihatun Ni'mah, S.Si.
C19: NIP. | D19: : | E19: 198008142009032003
C20: Pangkat/Gol. | D20: : | E20: Penata Tingkat I, III/d
C21: Jabatan | D21: : | E21: Guru Ahli Muda
C22: 2. Nama | D22: : | E22: -
C23: NIP | D23: : | E23: -
C24: Pangkat/Gol. | D24: : | E24: -
C25: Jabatan | D25: : | E25: -
B27: Untuk : | C27: Bimbingan Teknis Penyusunan Perangkat Pembelajaran Berbasis IT bagi Guru
C28: Hotel Front One HK Resort Semarang
C29: Rabu s.d. Jumat, 11 s.d. 13 Juni 2025
F32: Ditetapkan di : Demak
F33: Pada Tanggal : | I33: 10 Juni 2025
F34: Kepala SMPN 2 Karangtengah
F35: Kab. Demak
F39: Priyantono, S.Pd., M.Pd.
F40: NIP. 196902251994031005

Sheet Sheet2
B2: PEMERINTAH KABUPATEN DEMAK
B3: SMP NEGERI 2 KARANGTENGAH
B4: Jalan Raya Donorejo Kec. Karangtengah Demak, Jawa Tengah 59561
B5: (0291) 6910950 Pos-el : smpn2.karangtengahdemak@yahoo.co.id
H7: Lembar ke | I7: : | J7: -
H8: Kode No | I8: : | J8: -
H9: Nomor | I9: : | J9: =Sheet1!B8 -> No : 800/106/2025
C11: SURAT PERINTAH PERJALANAN DINAS
B13: 1. | C13: Pejabat Berwenang Yang Memberi Perintah | G13: Kepala SMPN 2 Karangtengah Kab. Demak
B14: 2. | C14: Nama/NIP Pegawai yang diperintahkan | G14: a. | H14: =Sheet1!E18 -> Malihatun Ni'mah, S.Si.
G15: b. | H15: =Sheet1!E19 -> 198008142009032003
B16: 3. | C16: a. Pangkat dan Golongan Ruang | G16: a. | H16: =Sheet1!E20 -> Penata Tingkat I, III/d
C17: b. Jabatan/Instansi | G17: b. | H17: =Sheet1!E21 -> Guru Ahli Muda
C18: c. Tingkat Biaya Perjalanan Dinas | G18: c. | H18: -
B19: 4. | C19: Maksud Perjalanan Dinas | G19: =Sheet1!C27 -> Bimbingan Teknis Penyusunan Perangkat Pembelajaran Berbasis IT bagi Guru
B22: 5. | C22: Alat Angkutan Yang Dipergunakan | G22: Kendaraan Pribadi/Umum/Dinas*
B23: 6. | C23: a. Tempat Berangkat | G23: a. | H23: SMP Negeri 2 Karangtengah
C24: b. Tempat Tujuan | G24: b. | H24: =Sheet1!$C$28 -> Hotel Front One HK Resort Semarang
B25: 7. | C25: a. Lamanya Perjalanan Dinas | G25: a. | H25: 3 (tiga) hari
C26: b. Tanggal berangkat | G26: b. | H26: 11 Juni 2025
C27: c. Tanggal Harus Kembali/Tiba Ditempat Baru* | G27: c. | H27: 13 Juni 2025
B28: 8. | C28: Pengikut Nama/NIP | G28: Golongan Ruang | I28: Tanda Tangan
C29: 1. Nama | I29: 1.
C30: NIP. | D30: …...................................................
C31: 2. Nama | I31: 2.
C32: NIP. | D32: …...................................................
C33: 3. Nama | I33: 3.
C34: NIP. | D34: …...................................................
C35: 4. Nama | I35: 4.
C36: NIP. | D36: …...................................................
C37: 5. Nama | I37: 5.
C38: NIP. | D38: …...................................................
B39: 9. | C39: Pembebanan Anggaran
C40: a. Instansi | G40: a. SMP Negeri 2 Karangtengah
C41: b. Mata Anggaran | G41: b. Perjalanan Dinas Dalam/Luar Daerah*
B42: 10. | C42: Keterangan Lain-Lain | G42: : -
B43: *coret yang tidak perlu
H44: =Sheet1!F32 -> Ditetapkan di : Demak
H45: =Sheet1!F33 -> Pada Tanggal : | J45: =Sheet1!I33 -> 10 Juni 2025
B46: Pelaksana SPPD | H46: =Sheet1!F34 -> Kepala SMPN 2 Karangtengah
...

Sheet Sheet3
F2: I. Berangkat dari : SMPN 2 Karangtengah
F3: (Tempat Kedudukan)
F4: Ke : | G4: =Sheet1!C28 -> Hotel Front One HK Resort Semarang
F5: Pada Tanggal : | H5: 11 Juni 2025
F7: Kepala SMP N 2 Karangtengah Kab. Demak
F12: =Sheet1!F39 -> Priyantono, S.Pd., M.Pd.
F13: =Sheet1!F40 -> NIP. 196902251994031005
B14: II. Tiba di : | C14: =G4 -> Hotel Front One HK Resort Semarang | F14: Berangkat Dari : | H14: SMPN 2 Karangtengah
B15: Pada Tanggal : | D15: 11 Juni 2025 | F15: Ke : | G15: =G4 -> Hotel Front One HK Resort Semarang
B16: Kepala : | F16: Pada Tanggal : | H16: =H5 -> 11 Juni 2025
F17: Kepala :
B20: …................................................ | F20: …................................................
B21: NIP. …....................................... | F21: NIP. ….......................................
B22: III. Tiba di : | F22: Berangkat Dari :
B23: Pada Tanggal : | F23: Ke :
B24: Kepala : | F24: Pada Tanggal :
F25: Kepala :
B28: …................................................ | F28: …................................................
B29: NIP. …....................................... | F29: NIP. ….......................................
B30: IV. Tiba di : | F30: Berangkat Dari :
B31: Pada Tanggal : | F31: Ke :
B32: Kepala : | F32: Pada Tanggal :
F33: Kepala :
B36: …................................................ | F36: …................................................
B37: NIP. …....................................... | F37: NIP. ….......................................
B38: V. Tiba di : | F38: Berangkat Dari :
B39: Pada Tanggal : | F39: Ke :
B40: Kepala : | F40: Pada Tanggal :
F41: Kepala :
B44: …................................................ | F44: …................................................
B45: NIP. …....................................... | F45: NIP. ….......................................
F46: VI. Telah diperiksa dengan keterangan bahwa perjalanan atas perintahnya dan semata-mata untuk kepentingan jabatan dalam waktu yang sesingkat-singkatnya.
H51: Demak, | I51: =Sheet1!I33 -> 10 Juni 2025
F53: Kepala SMPN 2 Karangtengah Kab. Demak
F57: =Sheet1!F39 -> Priyantono, S.Pd., M.Pd.
F58: =Sheet1!F40 -> NIP. 196902251994031005
B59: VII. Catatan Lain-Lain
B60: VIII. PERHATIAN
B61: Pejabat yang berwenang menerbitkan SPPD, pegawai yang melakukan perjalanan Dinas, para pejabat yang mengesahkan tanggal berangkat/tiba, serta bendaharawan bertanggungjawab berdasarkan peraturan-peraturan Keuangan Negara apabila Negara menderita rugi akibat kesalahan, kelalaian dan kealpaannya.

Sheet Sheet4
B2: LAPORAN PELAKSANAAN KEGIATAN
B4: 1. Hari, Tanggal | C4: : | D4: =Sheet1!C29 -> Rabu s.d. Jumat, 11 s.d. 13 Juni 2025
B5: 2. Tempat | C5: : | D5: =Sheet1!C28 -> Hotel Front One HK Resort Semarang
B6: 3. Waktu | C6: : | D6: -
B7: 4. Kegiatan | C7: : | D7: =Sheet1!_Hlk173475416 -> Bimbingan Teknis Penyusunan Perangkat Pembelajaran Berbasis IT bagi Guru
B9: 5. Hasil Kegiatan | C9: :
B11: ….........................…..............................................................................................
B12: ….........................…..............................................................................................
B13: ….........................…..............................................................................................
B14: ….........................…..............................................................................................
B15: ….........................…..............................................................................................
B16: ….........................…..............................................................................................
B17: ….........................…..............................................................................................
B18: ….........................…..............................................................................................
B19: ….........................…..............................................................................................
B20: ….........................…..............................................................................................
B21: ….........................…..............................................................................................
B22: ….........................…..............................................................................................
B23: ….........................…..............................................................................................
B25: 6. Dokumentasi | C25: :
B37: Pelaksana SPPD | F37: Kepala SMPN 2 Karangtengah
F38: Kab. Demak
B42: =Sheet2!B52 -> Malihatun Ni'mah, S.Si. | F42: =Sheet1!F39 -> Priyantono, S.Pd., M.Pd.
B43: =Sheet1!E19 -> 198008142009032003 | F43: =Sheet1!F40 -> NIP. 196902251994031005
