Workbook
Name _Hlk173475416: Sheet1!$C$50

Sheet Sheet1
B1: PEMERINTAH KABUPATEN DEMAK
B2: SMP NEGERI 2 KARANGTENGAH
B3: Jalan Raya Donorejo Kec. Karangtengah Demak, Jawa Tengah 59561
B4: (0291) 6910950 Pos-el : smpn2.karangtengahdemak@yahoo.co.id
B6: SURAT PERINTAH TUGAS
B7: No : 800/…................./2025
B9: Dasar : | C9: 1. Peraturan Menteri Keuangan Nomor 113/PMK.05/2012
C10: 2. Peraturan Pemerintah Nomor 12 Tahun 2019
C11: 3. Peraturan Daerah Kabupaten Demak Nomor 7 Tahun 2021
C12: 4. Peraturan Bupati Demak Nomor 53 Tahun 2021
C13: 5. Peraturan Bupati Demak Nomor 29 Tahun 2023
B15: MEMERINTAHKAN :
B17: Kepada : | C17: 1. Nama | D17: : | E17: Supriyono, S.Pd.
C18: NIP. | D18: : | E18: 196808212006041008
C19: Pangkat/Gol. | D19: : | E19: Penata Tingkat I, III/d
C20: Jabatan | D20: : | E20: Wakil Kepala Sekolah, Waka Kesiswaan
C21: 2. Nama | D21: : | E21: Malihatun Ni'mah, S.Si.
C22: NIP | D22: : | E22: 198008142009032003
C23: Pangkat/Gol. | D23: : | E23: Penata Tingkat I, III/d
C24: Jabatan | D24: : | E24: Waka Kurikurum
C25: 3. Nama | D25: : | E25: Khoirun Ni'am, S.E.
C26: NIP. | D26: : | E26: 198402282022211014
C27: Pangkat/Gol. | D27: : | E27: IX
C28: Jabatan | D28: : | E28: Waka Sarpras
C29: 4. Nama | D29: : | E29: Paulus Mauljono, S.Pd.
... C48: Jabatan | D48: : | E48: Guru Pembina
B50: Untuk : | C50: Melaksanakan Praktik Baik (Outing Class)
C51: Kembang Langit, Kab. Batang
C52: Rabu, 30 April 2025
C53: Pukul 07.00 WIB - selesai
F55: Ditetapkan di : Demak
F56: Pada Tanggal : | I56: 29 April 2025
F57: Kepala SMP Negeri 2 Karangtengah
F58: Kab. Demak
F62: Priyantono, S.Pd., M.Pd.
F63: NIP. 196902251994031005

Sheet Sheet2
B1: PEMERINTAH KABUPATEN DEMAK
B2: SMP NEGERI 2 KARANGTENGAH
B3: Jalan Raya Donorejo Kec. Karangtengah Demak, Jawa Tengah 59561
B4: (0291) 6910950 Pos-el : smpn2.karangtengahdemak@yahoo.co.id
H6: Lembar ke | I6: :
H7: Kode No | I7: :
H8: Nomor | I8: : | J8: =Sheet1!B7 -> No : 800/…................./2025
C10: SURAT PERINTAH PERJALANAN DINAS
B12: 1. | C12: Pejabat Berwenang Yang Memberi Perintah | G12: Kepala SMP Negeri 2 Karangtengah Kab. Demak
B13: 2. | C13: Nama/NIP Pegawai yang diperintahkan | G13: a. | H13: =Sheet1!E17 -> Supriyono, S.Pd.
G14: b. | H14: =Sheet1!E18 -> 196808212006041008
G15: a. | H15: =Sheet1!E21 -> Malihatun Ni'mah, S.Si.
G16: b. | H16: =Sheet1!E18 -> 196808212006041008
G17: a. | H17: =Sheet1!E25 -> Khoirun Ni'am, S.E.
G18: b. | H18: =Sheet1!E26 -> 198402282022211014
G19: a. | H19: =Sheet1!E29 -> Paulus Mauljono, S.Pd.
G20: b. | H20: =Sheet1!E30 -> 196609271989031007
G21: a. | H21: =Sheet1!E33 -> Dewi Nur Khalimah, S.Pd., M.Pd.
G22: b. | H22: =Sheet1!E33 -> Dewi Nur Khalimah, S.Pd., M.Pd.
G23: a. | H23: =Sheet1!E37 -> Septia Nurkhalisa, S.Pd.
G24: b. | H24: =Sheet1!E38 -> 199709062020122024
G25: a. | H25: =Sheet1!E41 -> Lulu' Aulia, S.Pd.
G26: b. | H26: =Sheet1!E42 -> 198704072022212005
G27: a. | H27: =Sheet1!E45 -> M. Nailul I'dad Firdaus, S.Pd.
G28: b. | H28: =Sheet1!E46 -> -
B29: 3. | C29: a. Pangkat dan Golongan Ruang | G29: a. | H29: =Sheet1!E19 -> Penata Tingkat I, III/d
G30: b. | H30: =Sheet1!E20 -> Wakil Kepala Sekolah, Waka Kesiswaan
G31: a. | H31: =Sheet1!E23 -> Penata Tingkat I, III/d
G32: b. | H32: =Sheet1!E24 -> Waka Kurikurum
G33: a. | H33: =Sheet1!E27 -> IX
G34: b. | H34: =Sheet1!E28 -> Waka Sarpras
G35: a. | H35: =Sheet1!E31 -> Pembina Utama Muda, IV/c
G36: b. | H36: =Sheet1!E32 -> Guru Ahli Madya
G37: a. | H37: =Sheet1!E35 -> Penata Tingkat I, III/d
G38: b. | H38: =Sheet1!E36 -> Guru Ahli Muda
C39: b. Jabatan/Instansi | G39: a. | H39: =Sheet1!E39 -> Penata Muda, III/a
G40: b. | H40: =Sheet1!E40 -> Guru Ahli Pertama
G41: a. | H41: =Sheet1!E43 -> IX
G42: b. | H42: =Sheet1!E44 -> Guru Ahli Pertama
G43: a. | H43: =Sheet1!E47 -> -
...

Sheet Sheet3
F1: I. Berangkat dari : SMP N 2 Karangtengah
F2: (Tempat Kedudukan)
F3: Ke : | G3: =Sheet1!C51 -> Kembang Langit, Kab. Batang
F4: Pada Tanggal : | H4: =Sheet1!I56 -> 29 April 2025
F6: Kepala SMP N 2 Karangtengah Kab. Demak
F11: =Sheet1!F62 -> Priyantono, S.Pd., M.Pd.
F12: =Sheet1!F63 -> NIP. 196902251994031005
B13: II. Tiba di : | C13: =G3 -> Kembang Langit, Kab. Batang | F13: Berangkat Dari : | H13: =Sheet2!H50 -> SMP Negeri 2 Karangtengah
B14: Pada Tanggal : | C14: =Sheet1!C52 -> Rabu, 30 April 2025 | F14: Ke : | G14: =Sheet1!C51 -> Kembang Langit, Kab. Batang
B15: Kepala : | F15: Pada Tanggal : | H15: =Sheet1!C52 -> Rabu, 30 April 2025
F16: Kepala :
B19: …................................................ | F19: …................................................
B20: NIP. …....................................... | F20: NIP. ….......................................
B21: III. Tiba di : | F21: Berangkat Dari :
B22: Pada Tanggal : | F22: Ke :
B23: Kepala : | F23: Pada Tanggal :
F24: Kepala :
B27: …................................................ | F27: …................................................
B28: NIP. …....................................... | F28: NIP. ….......................................
B29: IV. Tiba di : | F29: Berangkat Dari :
B30: Pada Tanggal : | F30: Ke :
B31: Kepala : | F31: Pada Tanggal :
F32: Kepala :
B35: …................................................ | F35: …................................................
B36: NIP. …....................................... | F36: NIP. ….......................................
B37: V. Tiba di : | F37: Berangkat Dari :
B38: Pada Tanggal : | F38: Ke :
B39: Kepala : | F39: Pada Tanggal :
F40: Kepala :
B43: …................................................ | F43: …................................................
B44: NIP. …....................................... | F44: NIP. ….......................................
F45: VI. Telah diperiksa dengan keterangan bahwa perjalanan atas perintahnya dan semata-mata untuk kepentingan jabatan dalam waktu yang sesingkat-singkatnya.
H50: Demak, | I50: =Sheet1!I56 -> 29 April 2025
F52: Kepala SMP Negeri 2 Karangtengah Kab. Demak
F56: =Sheet1!F62 -> Priyantono, S.Pd., M.Pd.
F57: =Sheet1!F63 -> NIP. 196902251994031005
B58: VII. Catatan Lain-Lain
B59: VIII. PERHATIAN
B60: Pejabat yang berwenang menerbitkan SPPD, pegawai yang melakukan perjalanan Dinas, para pejabat yang mengesahkan tanggal berangkat/tiba, serta bendaharawan bertanggungjawab berdasarkan peraturan-peraturan Keuangan Negara apabila Negara menderita rugi akibat kesalahan, kelalaian dan kealpaannya.

Sheet Sheet4
B1: LAPORAN PELAKSANAAN KEGIATAN
B3: 1. Hari, Tanggal | C3: : | D3: =Sheet1!C52 -> Rabu, 30 April 2025
B4: 2. Tempat | C4: : | D4: =Sheet1!C51 -> Kembang Langit, Kab. Batang
B5: 3. Waktu | C5: : | D5: =Sheet1!C53 -> Pukul 07.00 WIB - selesai
B6: 4. Kegiatan | C6: : | D6: =Sheet1!_Hlk173475416 -> Melaksanakan Praktik Baik (Outing Class)
B8: 5. Hasil Kegiatan | C8: :
B10: ….........................…...............................................................................................................
B11: ….........................…...............................................................................................................
B12: ….........................…...............................................................................................................
B13: ….........................…...............................................................................................................
B14: ….........................…...............................................................................................................
B15: ….........................…...............................................................................................................
B16: ….........................…...............................................................................................................
B17: ….........................…...............................................................................................................
B18: ….........................…...............................................................................................................
B19: ….........................…...............................................................................................................
B20: ….........................…...............................................................................................................
B21: ….........................…...............................................................................................................
B22: ….........................…...............................................................................................................
B24: 6. Dokumentasi | C24: :
B36: Pelaksana SPPD | G36: Pelaksana SPPD
B40: =Sheet2!B76 -> Supriyono, S.Pd. | G40: =Sheet2!I76 -> Malihatun Ni'mah, S.Si.
B41: =Sheet2!C77 -> 196808212006041008 | G41: =Sheet2!J77 -> 198008142009032003
B43: Pelaksana SPPD | G43: Pelaksana SPPD
B47: =Sheet2!B84 -> Paulus Mauljono, S.Pd. | G47: =Sheet2!I84 -> Khoirun Ni'am, S.E.
B48: =Sheet2!C85 -> 196609271989031007 | G48: =Sheet2!J85 -> 198402282022211014
B50: Pelaksana SPPD | G50: Pelaksana SPPD
B54: =Sheet1!E33 -> Dewi Nur Khalimah, S.Pd., M.Pd. | G54: =Sheet1!E37 -> Septia Nurkhalisa, S.Pd.
B55: =Sheet1!E34 -> 198711082010012013 | G55: =Sheet1!E38 -> 199709062020122024
B57: Pelaksana SPPD | G57: Pelaksana SPPD
B61: =Sheet2!B100 -> Lulu' Aulia, S.Pd. | G61: =Sheet2!I100 -> M. Nailul I'dad Firdaus, S.Pd.
B62: =Sheet2!C101 -> 198704072022212005 | G62: =Sheet1!E46 -> -
B64: Kepala SMP Negeri 2 Karangtengah
B65: Kab. Demak
B69: =Sheet1!F62 -> Priyantono, S.Pd., M.Pd.
B70: =Sheet1!F63 -> NIP. 196902251994031005
